Workbook

Sheet ii-excel-diff
A1: エクセルファイルの比較・差分結果報告書
I2: check1 | J2: check2 | K2: review
B3: 以下のエクセルファイルを比較・確認したので、差分結果について報告します
C5: ファイル(L) C:\sample-old.xlsx
C6: ファイル(R) C:\sample-new.xlsx
B8: 報告の要約を以下に列挙します
C10: 本書の活用手順
C11: 1. 差分を確認する：詳細シートで、Ｆ列に "x" のある行の ＤＥＧ列 に必要事項を記入する
C12: 2. 差分を確認する：本シート（下表）で ＩＪ列 が OK になることを確認する （NG の場合、↑ の対応漏れです）
C13: 3. 報告をまとめる：「何と何（前提：ファイルの素性）」 を 「なんのため（目的）」 に比較したのか 「ゴールの状態は何か（目標）」 を、この手順を記載した領域に記載する
C14: 4. 報告をまとめる：詳細シートを確認した結果の要約やポイント、報告すべきことを、この手順を記載した領域に列挙する
B19: シート毎のツールによる比較結果、および その結果の目視確認結果を下表に記します
C21: シート名 | D21: L | E21: R | F21: 差分 | G21: 差分行数 | H21: 備考 | I21: check1 | J21: check2
C22: ii-path-maker | D22: あり | E22: あり | F22: =IF(G22 <> 0, "あり", "なし") -> あり | G22: =COUNTIF('ii-path-maker'!F:F, "x") -> 6 | I22: =IF(SUMPRODUCT(('ii-path-maker'!F:F="x")*('ii-path-maker'!D:D<>""))=G22, "OK", "NG") -> NG | J22: =IF(SUMPRODUCT(('ii-path-maker'!F:F="x")*('ii-path-maker'!E:E<>""))=G22, "OK", "NG") -> NG
C23: ごみ settings | D23: あり | E23: あり | F23: =IF(G23 <> 0, "あり", "なし") -> なし | G23: =COUNTIF('ごみ settings'!F:F, "x") -> 0 | I23: =IF(SUMPRODUCT(('ごみ settings'!F:F="x")*('ごみ settings'!D:D<>""))=G23, "OK", "NG") -> OK | J23: =IF(SUMPRODUCT(('ごみ settings'!F:F="x")*('ごみ settings'!E:E<>""))=G23, "OK", "NG") -> OK
B25: 詳細は各シートを参照ください
B27: ＜補足・注意事項＞
B28: ・本シート（上表）の Ｇ列 で示す数値は、詳細シートの Ｆ列 が "x" の行数を入れています
B29: ・本シート（上表）の ＩＪ列 で示す値 (OK/NG) は、詳細シートの差分のあるすべての行の ＤＥ列 に値が入っていたら OK を入れ、
B30: そうでなければ NG を入れています
B31: ・詳細シートの Ｎ列 以降に、３つの領域に分けて、左からファイル（L）のシートの内容、ファイル（R）のシートの内容、
B32: ファイル（L）/（R）の差分を１つにまとめたシートの内容を入れています
B33: ・詳細シートで差分のある行は、Ｆ列 に "x" を入れ、該当する差分のあるセルは薄紫塗にしています
B34: ・比較に使用したオリジナルのシートを " >>> ORG SHEET >>> " 以降にコピーしています
B35: ・コピーした際のシート名の接頭語には、左に配置したエクセルは "L_" 、右に配置したエクセルは "R_" をつけています
B36: ・計算式の入ったセルは、セルの値をコピー・比較します
B37: ・オブジェクト、メモ、コメント、セル結合、行・列の幅などは非対応です
B39: Created by ii-excel-diff v.1.09 on 2026/03/14 16:45:57. It took 0:00:9.65 second. threshold=0.7.

Sheet ii-path-maker
A1: # | B1: 結合文字(L) | C1: 結合文字(R) | D1: check1 | E1: check2 | F1: 差分有無 | G1: 差分理由 | O1: ii-path-maker | P1: C:\sample-old.xlsx | CI1: ii-path-maker | CJ1: C:\sample-new.xlsx | FC1: C:\sample-new.xlsx
A2: label1 | B2: label2 | C2: label3 | D2: label4 | E2: label5 | F2: label6 | G2: label7 | H2: label8 | I2: label9 | J2: label10 | K2: label11 | L2: label12 | M2: label13 | N2: label14 | O2: label15 | P2: label16 | Q2: label17 | R2: label18 | S2: label19 | T2: label20 | U2: label21 | V2: label22 | W2: label23 | X2: label24 | Y2: label25 | Z2: label26 | AA2: label27 | AB2: label28 | AC2: label29 | AD2: label30 | AE2: label31 | AF2: label32 | AG2: label33 | AH2: label34 | AI2: label35 | AJ2: label36 | AK2: label37 | AL2: label38 | AM2: label39 | AN2: label40 | AO2: label41 | AP2: label42 | AQ2: label43 | AR2: label44 | AS2: label45 | AT2: label46 | AU2: label47 | AV2: label48 | AW2: label49 | AX2: label50 | AY2: label51 | AZ2: label52 | BA2: label53 | BB2: label54 | BC2: label55 | BD2: label56 | BE2: label57 | BF2: label58 | BG2: label59 | BH2: label60 | BI2: label61 | BJ2: label62 | BK2: label63 | BL2: label64 | BM2: label65 | BN2: label66 | BO2: label67 | BP2: label68 | BQ2: label69 | BR2: label70 | BS2: label71 | BT2: label72 | BU2: label73 | BV2: label74 | BW2: label75 | BX2: label76 | BY2: label77 | BZ2: label78 | CA2: label79 | CB2: label80 | CC2: label81 | CD2: label82 | CE2: label83 | CF2: label84 | CG2: label85 | CH2: label86 | CI2: label87 | CJ2: label88 | CK2: label89 | CL2: label90 | CM2: label91 | CN2: label92 | CO2: label93 | CP2: label94 | CQ2: label95 | CR2: label96 | CS2: label97 | CT2: label98 | CU2: label99 | CV2: label100 | CW2: label101 | CX2: label102 | CY2: label103 | CZ2: label104 | DA2: label105 | DB2: label106 | DC2: label107 | DD2: label108 | DE2: label109 | DF2: label110 | DG2: label111 | DH2: label112 | DI2: label113 | DJ2: label114 | DK2: label115 | DL2: label116 | DM2: label117 | DN2: label118 | DO2: label119 | DP2: label120 | DQ2: label121 | DR2: label122 | DS2: label123 | DT2: label124 | DU2: label125 | DV2: label126 | DW2: label127 | DX2: label128 | DY2: label129 | DZ2: label130 | EA2: label131 | EB2: label132 | EC2: label133 | ED2: label134 | EE2: label135 | EF2: label136 | EG2: label137 | EH2: label138 | EI2: label139 | EJ2: label140 | EK2: label141 | EL2: label142 | EM2: label143 | EN2: label144 | EO2: label145 | EP2: label146 | EQ2: label147 | ER2: label148 | ES2: label149 | ET2: label150 | EU2: label151 | EV2: label152 | EW2: label153 | EX2: label154 | EY2: label155 | EZ2: label156 | FA2: label157 | FB2: label158 | FC2: label159 | FD2: label160 | FE2: label161 | FF2: label162 | FG2: label163 | FH2: label164 | FI2: label165 | FJ2: label166 | FK2: label167 | FL2: label168 | FM2: label169 | FN2: label170 | FO2: label171 | FP2: label172 | FQ2: label173 | FR2: label174 | FS2: label175 | FT2: label176 | FU2: label177 | FV2: label178 | FW2: label179 | FX2: label180 | FY2: label181 | FZ2: label182 | GA2: label183 | GB2: label184 | GC2: label185 | GD2: label186 | GE2: label187 | GF2: label188 | GG2: label189 | GH2: label190 | GI2: label191 | GJ2: label192 | GK2: label193 | GL2: label194 | GM2: label195 | GN2: label196 | GO2: label197 | GP2: label198 | GQ2: label199 | GR2: label200 | GS2: label201 | GT2: label202 | GU2: label203 | GV2: label204 | GW2: label205 | GX2: label206 | GY2: label207 | GZ2: label208 | HA2: label209 | HB2: label210 | HC2: label211 | HD2: label212 | HE2: label213 | HF2: label214 | HG2: label215 | HH2: label216 | HI2: label217 | HJ2: label218 | HK2: label219 | HL2: label220 | HM2: label221 | HN2: label222 | HO2: label223 | HP2: label224 | HQ2: label225 | HR2: label226 | HS2: label227 | HT2: label228 | HU2: label229
A3: =ROW() - 2 -> 1 | B3: ii-path-maker 操作説明書 | C3: ii-path-maker 操作説明書 | H3: 1.00 | N3: 1 | O3: ii-path-maker 操作説明書 | CH3: 1 | CI3: ii-path-maker 操作説明書 | FB3: 1 | FC3: ii-path-maker 操作説明書 | HV3: 1
A4: =ROW() - 2 -> 2 | H4: 1.00 | N4: 2 | CH4: 2 | FB4: 2 | HV4: 2
A5: =ROW() - 2 -> 3 | B5: ■ 使い方 ■ どういう使い方を想定しているか | C5: ■ 使い方 ■ どういう使い方を想定しているか | H5: 1.00 | N5: 3 | P5: ■ 使い方 | BO5: ■ どういう使い方を想定しているか | CH5: 3 | CJ5: ■ 使い方 | EI5: ■ どういう使い方を想定しているか | FB5: 3 | FD5: ■ 使い方 | HC5: ■ どういう使い方を想定しているか | HV5: 3
A6: =ROW() - 2 -> 4 | B6: 設定ファイルを作成して、以下のいずれかのパターンで ii-path-maker に食わせます 例： とある svn のファイル構成 左記のような ファイル構成のとき、 | C6: 設定ファイルを作成して、以下のいずれかのパターンで ii-path-maker に食わせます 例： とある svn のファイル構成 左記のような ファイル構成のとき、 | H6: 1.00 | N6: 4 | Q6: 設定ファイルを作成して、以下のいずれかのパターンで ii-path-maker に食わせます | AX6: 例： とある svn のファイル構成 | BP6: 左記のような ファイル構成のとき、 | CH6: 4 | CK6: 設定ファイルを作成して、以下のいずれかのパターンで ii-path-maker に食わせます | DR6: 例： とある svn のファイル構成 | EJ6: 左記のような ファイル構成のとき、 | FB6: 4 | FE6: 設定ファイルを作成して、以下のいずれかのパターンで ii-path-maker に食わせます | GL6: 例： とある svn のファイル構成 | HD6: 左記のような ファイル構成のとき、 | HV6: 4
A7: =ROW() - 2 -> 5 | B7: c:\svn 具体的には | C7: c:\svn 具体的には | H7: 1.00 | N7: 5 | AY7: c:\svn | BP7: 具体的には | CH7: 5 | DS7: c:\svn | EJ7: 具体的には | FB7: 5 | GM7: c:\svn | HD7: 具体的には | HV7: 5
A8: =ROW() - 2 -> 6 | B8: <パターン Drag&Drop> <パターン 送る> +- repos ・Aプロジェクトには派生プロジェクト(40)がある | C8: <パターン Drag&Drop> <パターン 送る> +- repos ・Aプロジェクトには派生プロジェクト(404)がある | F8: x | H8: 1.00 | N8: 6 | Q8: <パターン Drag&Drop> | AF8: <パターン 送る> | AY8: +- repos | BQ8: ・Aプロジェクトには派生プロジェクト(40)がある | CH8: 6 | CK8: <パターン Drag&Drop> | CZ8: <パターン 送る> | DS8: +- repos | EK8: ・Aプロジェクトには派生プロジェクト(404)がある | FB8: 6 | FE8: <パターン Drag&Drop> | FT8: <パターン 送る> | GM8: +- repos | HE8: ・Aプロジェクトには派生プロジェクト(40)がある ⇒ ・Aプロジェクトには派生プロジェクト(404)がある | HV8: 6
A9: =ROW() - 2 -> 7 | B9: | +- branches ・派生プロジェクトにはスナップショットが存在する | C9: | +- branches ・派生プロジェクトにはスナップショットが存在する | H9: 1.00 | N9: 7 | AY9: | +- branches | BQ9: ・派生プロジェクトにはスナップショットが存在する | CH9: 7 | DS9: | +- branches | EK9: ・派生プロジェクトにはスナップショットが存在する | FB9: 7 | GM9: | +- branches | HE9: ・派生プロジェクトにはスナップショットが存在する | HV9: 7
A10: =ROW() - 2 -> 8 | B10: | | +- A_404 ・最新は trunk 以下に管理されている | C10: | | +- A_404 ※マイルストーン毎に構成管理されており、 | F10: x | H10: 0.85 | N10: 8 | AY10: | | +- A_404 | BQ10: ・最新は trunk 以下に管理されている | CH10: 8 | DS10: | | +- A_404 | EK10: ※マイルストーン毎に構成管理されており、 | FB10: 8 | GM10: | | +- A_404 | HE10: ・最新は trunk 以下に管理されている ⇒ ※マイルストーン毎に構成管理されており、 | HV10: 8
A11: =ROW() - 2 -> 9 | B11: | | | +- design ・プロジェクトをまたいだ標準となる書類がある | C11: | | | +- design 同じファイル名のファイルが複数存在する | F11: x | H11: 0.82 | N11: 9 | AY11: | | | +- design | BQ11: ・プロジェクトをまたいだ標準となる書類がある | CH11: 9 | DS11: | | | +- design | EK11: 同じファイル名のファイルが複数存在する | FB11: 9 | GM11: | | | +- design | HE11: ・プロジェクトをまたいだ標準となる書類がある ⇒ 同じファイル名のファイルが複数存在する | HV11: 9
A12: =ROW() - 2 -> 10 | B12: | | | +- mng ※trunk/prj/A 以外にも A で参照する資料がある | C12: | | | +- mng ・最新は trunk 以下に管理されている | F12: x | H12: 0.84 | N12: 10 | AY12: | | | +- mng | BQ12: ※trunk/prj/A 以外にも A で参照する資料がある | CH12: 10 | DS12: | | | +- mng | EK12: ・最新は trunk 以下に管理されている | FB12: 10 | GM12: | | | +- mng | HE12: ※trunk/prj/A 以外にも A で参照する資料がある ⇒ ・最新は trunk 以下に管理されている | HV12: 10
A13: =ROW() - 2 -> 11 | B13: | | | | +- issue.xlsx | C13: | | | | +- issue.xlsx ・プロジェクトをまたいだ標準となる書類がある | F13: x | H13: 0.89 | N13: 11 | AY13: | | | | +- issue.xlsx | CH13: 11 | DS13: | | | | +- issue.xlsx | EK13: ・プロジェクトをまたいだ標準となる書類がある | FB13: 11 | GM13: | | | | +- issue.xlsx | HE13: ⇒ ・プロジェクトをまたいだ標準となる書類がある | HV13: 11
A14: =ROW() - 2 -> 12 | B14: <パターン ダブルクリック> | | | | +- plan.xlsx | C14: <パターン ダブルクリック> | | | | +- plan.xlsx ※trunk/prj/A 以外にも A で参照する資料がある | F14: x | H14: 0.86 | N14: 12 | Q14: <パターン ダブルクリック> | AY14: | | | | +- plan.xlsx | CH14: 12 | CK14: <パターン ダブルクリック> | DS14: | | | | +- plan.xlsx | EK14: ※trunk/prj/A 以外にも A で参照する資料がある | FB14: 12 | FE14: <パターン ダブルクリック> | GM14: | | | | +- plan.xlsx | HE14: ⇒ ※trunk/prj/A 以外にも A で参照する資料がある | HV14: 12
A15: =ROW() - 2 -> 13 | B15: | | | | +- risk.xlsx という状態で、 | C15: | | | | +- risk.xlsx という状態で、 | H15: 1.00 | N15: 13 | AY15: | | | | +- risk.xlsx | BP15: という状態で、 | CH15: 13 | DS15: | | | | +- risk.xlsx | EJ15: という状態で、 | FB15: 13 | GM15: | | | | +- risk.xlsx | HD15: という状態で、 | HV15: 13
A16: =ROW() - 2 -> 14 | B16: | | | +- spec Aプロジェクトの情報を参照するにしても、 | C16: | | | +- spec Aプロジェクトの情報を参照するにしても、 | H16: 1.00 | N16: 14 | AY16: | | | +- spec | BP16: Aプロジェクトの情報を参照するにしても、 | CH16: 14 | DS16: | | | +- spec | EJ16: Aプロジェクトの情報を参照するにしても、 | FB16: 14 | GM16: | | | +- spec | HD16: Aプロジェクトの情報を参照するにしても、 | HV16: 14
A17: =ROW() - 2 -> 15 | B17: | | | | +- spec_system_design.xlsx 経験をもとにどこに何があるか探しに行く | C17: | | | | +- spec_system_design.xlsx 経験をもとにどこに何があるか探しに行く | H17: 1.00 | N17: 15 | AY17: | | | | +- spec_system_design.xlsx | BP17: 経験をもとにどこに何があるか探しに行く | CH17: 15 | DS17: | | | | +- spec_system_design.xlsx | EJ17: 経験をもとにどこに何があるか探しに行く | FB17: 15 | GM17: | | | | +- spec_system_design.xlsx | HD17: 経験をもとにどこに何があるか探しに行く | HV17: 15
A18: =ROW() - 2 -> 16 | B18: | +- tags 必要がある | C18: | +- tags 必要がある | H18: 1.00 | N18: 16 | AY18: | +- tags | BP18: 必要がある | CH18: 16 | DS18: | +- tags | EJ18: 必要がある | FB18: 16 | GM18: | +- tags | HD18: 必要がある | HV18: 16
A19: =ROW() - 2 -> 17 | B19: | | +- A_404_250122_DR | C19: | | +- A_404_250122_DR | H19: 1.00 | N19: 17 | AY19: | | +- A_404_250122_DR | CH19: 17 | DS19: | | +- A_404_250122_DR | FB19: 17 | GM19: | | +- A_404_250122_DR | HV19: 17
A20: =ROW() - 2 -> 18 | B20: | | | +- design そんなお困りごとを解決するために | C20: | | | +- design そんなお困りごとを解決するために | H20: 1.00 | N20: 18 | AY20: | | | +- design | BP20: そんなお困りごとを解決するために | CH20: 18 | DS20: | | | +- design | EJ20: そんなお困りごとを解決するために | FB20: 18 | GM20: | | | +- design | HD20: そんなお困りごとを解決するために | HV20: 18
A21: =ROW() - 2 -> 19 | B21: | | | +- mng ある程度ルールのある置き方がされている資料の | C21: | | | +- mng ある程度ルールのある置き方がされている資料の | H21: 1.00 | N21: 19 | AY21: | | | +- mng | BP21: ある程度ルールのある置き方がされている資料の | CH21: 19 | DS21: | | | +- mng | EJ21: ある程度ルールのある置き方がされている資料の | FB21: 19 | GM21: | | | +- mng | HD21: ある程度ルールのある置き方がされている資料の | HV21: 19
A22: =ROW() - 2 -> 20 | B22: | | | | +- issue.xlsx 一覧を作成するツールを用意しました | C22: | | | | +- issue.xlsx 一覧を作成するツールを用意しました | H22: 1.00 | N22: 20 | AY22: | | | | +- issue.xlsx | BP22: 一覧を作成するツールを用意しました | CH22: 20 | DS22: | | | | +- issue.xlsx | EJ22: 一覧を作成するツールを用意しました | FB22: 20 | GM22: | | | | +- issue.xlsx | HD22: 一覧を作成するツールを用意しました | HV22: 20
A23: =ROW() - 2 -> 21 | B23: ■ 結果の確認 | | | | +- plan.xlsx | C23: ■ 結果の確認 | | | | +- plan.xlsx | H23: 1.00 | N23: 21 | P23: ■ 結果の確認 | AY23: | | | | +- plan.xlsx | CH23: 21 | CJ23: ■ 結果の確認 | DS23: | | | | +- plan.xlsx | FB23: 21 | FD23: ■ 結果の確認 | GM23: | | | | +- plan.xlsx | HV23: 21
A24: =ROW() - 2 -> 22 | B24: 実行いただきますと、設定ファイルのあるディレクトリに以下のファイルが作成されます | | | | +- risk.xlsx 本ツールを使って、以下を指定することで | C24: 実行いただきますと、設定ファイルのあるディレクトリに以下のファイルが作成されます | | | | +- risk.xlsx 本ツールを使って、以下を指定することで | H24: 1.00 | N24: 22 | Q24: 実行いただきますと、設定ファイルのあるディレクトリに以下のファイルが作成されます | AY24: | | | | +- risk.xlsx | BP24: 本ツールを使って、以下を指定することで | CH24: 22 | CK24: 実行いただきますと、設定ファイルのあるディレクトリに以下のファイルが作成されます | DS24: | | | | +- risk.xlsx | EJ24: 本ツールを使って、以下を指定することで | FB24: 22 | FE24: 実行いただきますと、設定ファイルのあるディレクトリに以下のファイルが作成されます | GM24: | | | | +- risk.xlsx | HD24: 本ツールを使って、以下を指定することで | HV24: 22
A25: =ROW() - 2 -> 23 | B25: ・結果帳票（設定ファイルの拡張子が xlsx に変わっているファイル） | | | +- spec ・資料の名称 | C25: ・結果帳票（設定ファイルの拡張子が xlsx に変わっているファイル） | | | +- spec ・資料の名称 | H25: 1.00 | N25: 23 | R25: ・結果帳票（設定ファイルの拡張子が xlsx に変わっているファイル） | AY25: | | | +- spec | BP25: ・資料の名称 | CH25: 23 | CL25: ・結果帳票（設定ファイルの拡張子が xlsx に変わっているファイル） | DS25: | | | +- spec | EJ25: ・資料の名称 | FB25: 23 | FF25: ・結果帳票（設定ファイルの拡張子が xlsx に変わっているファイル） | GM25: | | | +- spec | HD25: ・資料の名称 | HV25: 23
A26: =ROW() - 2 -> 24 | B26: ※同名ファイルがあった場合、ii-path-maker_<ファイル名>_<数値>.xlsx を作成します | | | | +- spec_system_design.xlsx ・ファイル名・フォルダ名の検索キーワード | C26: ※同名ファイルがあった場合、ii-path-maker_<ファイル名>_<数値>.xlsx を作成します | | | | +- spec_system_design.xlsx ・ファイル名・フォルダ名の検索キーワード | H26: 1.00 | N26: 24 | R26: ※同名ファイルがあった場合、ii-path-maker_<ファイル名>_<数値>.xlsx を作成します | AY26: | | | | +- spec_system_design.xlsx | BP26: ・ファイル名・フォルダ名の検索キーワード | CH26: 24 | CL26: ※同名ファイルがあった場合、ii-path-maker_<ファイル名>_<数値>.xlsx を作成します | DS26: | | | | +- spec_system_design.xlsx | EJ26: ・ファイル名・フォルダ名の検索キーワード | FB26: 24 | FF26: ※同名ファイルがあった場合、ii-path-maker_<ファイル名>_<数値>.xlsx を作成します | GM26: | | | | +- spec_system_design.xlsx | HD26: ・ファイル名・フォルダ名の検索キーワード | HV26: 24
A27: =ROW() - 2 -> 25 | B27: ・実行前の設定ファイル（設定ファイル名と拡張子の間に _bk が入っているファイル） | | +- A_404_250222_FIX ・だいたいここらへんにあるはず！の所在 | C27: ・実行前の設定ファイル（設定ファイル名と拡張子の間に _bk が入っているファイル） | | +- A_404_250222_FIX ・だいたいここらへんにあるはず！の所在 | H27: 1.00 | N27: 25 | R27: ・実行前の設定ファイル（設定ファイル名と拡張子の間に _bk が入っているファイル） | AY27: | | +- A_404_250222_FIX | BP27: ・だいたいここらへんにあるはず！の所在 | CH27: 25 | CL27: ・実行前の設定ファイル（設定ファイル名と拡張子の間に _bk が入っているファイル） | DS27: | | +- A_404_250222_FIX | EJ27: ・だいたいここらへんにあるはず！の所在 | FB27: 25 | FF27: ・実行前の設定ファイル（設定ファイル名と拡張子の間に _bk が入っているファイル） | GM27: | | +- A_404_250222_FIX | HD27: ・だいたいここらへんにあるはず！の所在 | HV27: 25
A28: =ROW() - 2 -> 26 | B28: ※同名ファイルがあった場合、上書きします | | | +- design | C28: ※同名ファイルがあった場合、上書きします | | | +- design | H28: 1.00 | N28: 26 | R28: ※同名ファイルがあった場合、上書きします | AY28: | | | +- design | CH28: 26 | CL28: ※同名ファイルがあった場合、上書きします | DS28: | | | +- design | FB28: 26 | FF28: ※同名ファイルがあった場合、上書きします | GM28: | | | +- design | HV28: 26
A29: =ROW() - 2 -> 27 | B29: ・結果帳票にパスを記したファイルの現物 | | | +- mng プロジェクトの資料一覧を作成します | C29: ・結果帳票にパスを記したファイルの現物 | | | +- mng プロジェクトの資料一覧を作成します | H29: 1.00 | N29: 27 | R29: ・結果帳票にパスを記したファイルの現物 | AY29: | | | +- mng | BP29: プロジェクトの資料一覧を作成します | CH29: 27 | CL29: ・結果帳票にパスを記したファイルの現物 | DS29: | | | +- mng | EJ29: プロジェクトの資料一覧を作成します | FB29: 27 | FF29: ・結果帳票にパスを記したファイルの現物 | GM29: | | | +- mng | HD29: プロジェクトの資料一覧を作成します | HV29: 27
A30: =ROW() - 2 -> 28 | B30: ※設定ファイルの settings で is_export に true を指定した場合のみ作成されます | | | | +- issue.xlsx | C30: ※設定ファイルの settings で is_export に true を指定した場合のみ作成されます | | | | +- issue.xlsx | H30: 1.00 | N30: 28 | R30: ※設定ファイルの settings で is_export に true を指定した場合のみ作成されます | AY30: | | | | +- issue.xlsx | CH30: 28 | CL30: ※設定ファイルの settings で is_export に true を指定した場合のみ作成されます | DS30: | | | | +- issue.xlsx | FB30: 28 | FF30: ※設定ファイルの settings で is_export に true を指定した場合のみ作成されます | GM30: | | | | +- issue.xlsx | HV30: 28
A31: =ROW() - 2 -> 29 | B31: ※同名ファイルがあった場合、ii-path-maker_<ファイル名>_<数値>.<拡張子> を作成します | | | | +- plan.xlsx オプション指定をすると | C31: ※同名ファイルがあった場合、ii-path-maker_<ファイル名>_<数値>.<拡張子> を作成します | | | | +- plan.xlsx オプション指定をすると | H31: 1.00 | N31: 29 | R31: ※同名ファイルがあった場合、ii-path-maker_<ファイル名>_<数値>.<拡張子> を作成します | AY31: | | | | +- plan.xlsx | BP31: オプション指定をすると | CH31: 29 | CL31: ※同名ファイルがあった場合、ii-path-maker_<ファイル名>_<数値>.<拡張子> を作成します | DS31: | | | | +- plan.xlsx | EJ31: オプション指定をすると | FB31: 29 | FF31: ※同名ファイルがあった場合、ii-path-maker_<ファイル名>_<数値>.<拡張子> を作成します | GM31: | | | | +- plan.xlsx | HD31: オプション指定をすると | HV31: 29
A32: =ROW() - 2 -> 30 | B32: | | | | +- risk.xlsx 資料を全て コピーして持ってきます | C32: | | | | +- risk.xlsx 資料を全て コピーして持ってきます | H32: 1.00 | N32: 30 | AY32: | | | | +- risk.xlsx | BP32: 資料を全て コピーして持ってきます | CH32: 30 | DS32: | | | | +- risk.xlsx | EJ32: 資料を全て コピーして持ってきます | FB32: 30 | GM32: | | | | +- risk.xlsx | HD32: 資料を全て コピーして持ってきます | HV32: 30
A33: =ROW() - 2 -> 31 | B33: 結果帳票は以下のようなものが出力されますので、出力後は自由にご活用くださいませ | | | +- spec | C33: 結果帳票は以下のようなものが出力されますので、出力後は自由にご活用くださいませ | | | +- spec | H33: 1.00 | N33: 31 | Q33: 結果帳票は以下のようなものが出力されますので、出力後は自由にご活用くださいませ | AY33: | | | +- spec | CH33: 31 | CK33: 結果帳票は以下のようなものが出力されますので、出力後は自由にご活用くださいませ | DS33: | | | +- spec | FB33: 31 | FE33: 結果帳票は以下のようなものが出力されますので、出力後は自由にご活用くださいませ | GM33: | | | +- spec | HV33: 31
A34: =ROW() - 2 -> 32 | B34: | | | | +- spec_system_design.xlsx ぜひ、ご活用くださいませ | C34: | | | | +- spec_system_design.xlsx ぜひ、ご活用くださいませ | H34: 1.00 | N34: 32 | AY34: | | | | +- spec_system_design.xlsx | BP34: ぜひ、ご活用くださいませ | CH34: 32 | DS34: | | | | +- spec_system_design.xlsx | EJ34: ぜひ、ご活用くださいませ | FB34: 32 | GM34: | | | | +- spec_system_design.xlsx | HD34: ぜひ、ご活用くださいませ | HV34: 32
A35: =ROW() - 2 -> 33 | B35: | +- trunk | C35: | +- trunk | H35: 1.00 | N35: 33 | AY35: | +- trunk | CH35: 33 | DS35: | +- trunk | FB35: 33 | GM35: | +- trunk | HV35: 33
A36: =ROW() - 2 -> 34 | B36: | | +- prj | C36: | | +- prj | H36: 1.00 | N36: 34 | AY36: | | +- prj | CH36: 34 | DS36: | | +- prj | FB36: 34 | GM36: | | +- prj | HV36: 34
A37: =ROW() - 2 -> 35 | B37: | | | +- A | C37: | | | +- A | H37: 1.00 | N37: 35 | AY37: | | | +- A | CH37: 35 | DS37: | | | +- A | FB37: 35 | GM37: | | | +- A | HV37: 35
A38: =ROW() - 2 -> 36 | B38: | | | | +- design | C38: | | | | +- design | H38: 1.00 | N38: 36 | AY38: | | | | +- design | CH38: 36 | DS38: | | | | +- design | FB38: 36 | GM38: | | | | +- design | HV38: 36
A39: =ROW() - 2 -> 37 | B39: | | | | +- mng | C39: | | | | +- mng | H39: 1.00 | N39: 37 | AY39: | | | | +- mng | CH39: 37 | DS39: | | | | +- mng | FB39: 37 | GM39: | | | | +- mng | HV39: 37
A40: =ROW() - 2 -> 38 | B40: | | | | | +- issue.xlsx | C40: | | | | | +- issue.xlsx | H40: 1.00 | N40: 38 | AY40: | | | | | +- issue.xlsx | CH40: 38 | DS40: | | | | | +- issue.xlsx | FB40: 38 | GM40: | | | | | +- issue.xlsx | HV40: 38
...

Sheet ごみ settings
A1: # | B1: 結合文字(L) | C1: 結合文字(R) | D1: check1 | E1: check2 | F1: 差分有無 | G1: 差分理由 | O1: ごみ settings | P1: C:\sample-old.xlsx | AM1: ごみ settings | AN1: C:\sample-new.xlsx | BK1: C:\sample-new.xlsx
A2: label1 | B2: label2 | C2: label3 | D2: label4 | E2: label5 | F2: label6 | G2: label7 | H2: label8 | I2: label9 | J2: label10 | K2: label11 | L2: label12 | M2: label13 | N2: label14 | O2: label15 | P2: label16 | Q2: label17 | R2: label18 | S2: label19 | T2: label20 | U2: label21 | V2: label22 | W2: label23 | X2: label24 | Y2: label25 | Z2: label26 | AA2: label27 | AB2: label28 | AC2: label29 | AD2: label30 | AE2: label31 | AF2: label32 | AG2: label33 | AH2: label34 | AI2: label35 | AJ2: label36 | AK2: label37 | AL2: label38 | AM2: label39 | AN2: label40 | AO2: label41 | AP2: label42 | AQ2: label43 | AR2: label44 | AS2: label45 | AT2: label46 | AU2: label47 | AV2: label48 | AW2: label49 | AX2: label50 | AY2: label51 | AZ2: label52 | BA2: label53 | BB2: label54 | BC2: label55 | BD2: label56 | BE2: label57 | BF2: label58 | BG2: label59 | BH2: label60 | BI2: label61 | BJ2: label62 | BK2: label63 | BL2: label64 | BM2: label65 | BN2: label66 | BO2: label67 | BP2: label68 | BQ2: label69 | BR2: label70 | BS2: label71 | BT2: label72 | BU2: label73 | BV2: label74 | BW2: label75 | BX2: label76 | BY2: label77 | BZ2: label78 | CA2: label79 | CB2: label80 | CC2: label81 | CD2: label82 | CE2: label83 | CF2: label84 | CG2: label85
A3: =ROW() - 2 -> 1 | B3: プロジェクトＡ（ベース：Ｘ、派生：α）の開発資料リスト ＜本シートの使い方> 1. タイトルを記載する | C3: プロジェクトＡ（ベース：Ｘ、派生：α）の開発資料リスト ＜本シートの使い方> 1. タイトルを記載する | H3: 1.00 | N3: 1 | O3: プロジェクトＡ（ベース：Ｘ、派生：α）の開発資料リスト | AE3: ＜本シートの使い方> 1. タイトルを記載する | AL3: 1 | AM3: プロジェクトＡ（ベース：Ｘ、派生：α）の開発資料リスト | BC3: ＜本シートの使い方> 1. タイトルを記載する | BJ3: 1 | BK3: プロジェクトＡ（ベース：Ｘ、派生：α）の開発資料リスト | CA3: ＜本シートの使い方> 1. タイトルを記載する | CH3: 1
A4: =ROW() - 2 -> 2 | H4: 1.00 | N4: 2 | AL4: 2 | BJ4: 2 | CH4: 2
A5: =ROW() - 2 -> 3 | B5: 参照パスリストnameドライブsvnプロジェクト管理設計仕様 入力欄 | C5: 参照パスリストnameドライブsvnプロジェクト管理設計仕様 入力欄 | H5: 1.00 | N5: 3 | O5: 参照パスリスト | P5: name | Q5: ドライブ | R5: svn | S5: プロジェクト | T5: 管理 | U5: 設計 | V5: 仕様 | AI5: 入力欄 | AL5: 3 | AM5: 参照パスリスト | AN5: name | AO5: ドライブ | AP5: svn | AQ5: プロジェクト | AR5: 管理 | AS5: 設計 | AT5: 仕様 | BG5: 入力欄 | BJ5: 3 | BK5: 参照パスリスト | BL5: name | BM5: ドライブ | BN5: svn | BO5: プロジェクト | BP5: 管理 | BQ5: 設計 | BR5: 仕様 | CE5: 入力欄 | CH5: 3
A6: =ROW() - 2 -> 4 | B6: pathc:\svn\trunk\prj\file:///c:/svn/repos/trunk/prj/A/mng/design/spec/ | C6: pathc:\svn\trunk\prj\file:///c:/svn/repos/trunk/prj/A/mng/design/spec/ | H6: 1.00 | N6: 4 | P6: path | Q6: c:\svn\trunk\prj\ | R6: file:///c:/svn/repos/trunk/prj/ | S6: A/ | T6: mng/ | U6: design/ | V6: spec/ | AL6: 4 | AN6: path | AO6: c:\svn\trunk\prj\ | AP6: file:///c:/svn/repos/trunk/prj/ | AQ6: A/ | AR6: mng/ | AS6: design/ | AT6: spec/ | BJ6: 4 | BL6: path | BM6: c:\svn\trunk\prj\ | BN6: file:///c:/svn/repos/trunk/prj/ | BO6: A/ | BP6: mng/ | BQ6: design/ | BR6: spec/ | CH6: 4
A7: =ROW() - 2 -> 5 | H7: 1.00 | N7: 5 | AL7: 5 | BJ7: 5 | CH7: 5
A8: =ROW() - 2 -> 6 | B8: 設定情報description派生αはベースＸから流用開発する 2. description を記載する | C8: 設定情報description派生αはベースＸから流用開発する 2. description を記載する | H8: 1.00 | N8: 6 | O8: 設定情報 | P8: description | Q8: 派生αはベースＸから流用開発する | AE8: 2. description を記載する | AL8: 6 | AM8: 設定情報 | AN8: description | AO8: 派生αはベースＸから流用開発する | BC8: 2. description を記載する | BJ8: 6 | BK8: 設定情報 | BL8: description | BM8: 派生αはベースＸから流用開発する | CA8: 2. description を記載する | CH8: 6
A9: =ROW() - 2 -> 7 | B9: 仕様書を以下に列挙する ※複数行可、１セル１行、行が不足した場合、 | C9: 仕様書を以下に列挙する ※複数行可、１セル１行、行が不足した場合、 | H9: 1.00 | N9: 7 | Q9: 仕様書を以下に列挙する | AE9: ※複数行可、１セル１行、行が不足した場合、 | AL9: 7 | AO9: 仕様書を以下に列挙する | BC9: ※複数行可、１セル１行、行が不足した場合、 | BJ9: 7 | BM9: 仕様書を以下に列挙する | CA9: ※複数行可、１セル１行、行が不足した場合、 | CH9: 7
A10: =ROW() - 2 -> 8 | B10: 7-9行目のいずれかを選択、右クリック | C10: 7-9行目のいずれかを選択、右クリック | H10: 1.00 | N10: 8 | AE10: 7-9行目のいずれかを選択、右クリック | AL10: 8 | BC10: 7-9行目のいずれかを選択、右クリック | BJ10: 8 | CA10: 7-9行目のいずれかを選択、右クリック | CH10: 8
A11: =ROW() - 2 -> 9 | B11: から コピー と コピーしたセルの挿入 | C11: から コピー と コピーしたセルの挿入 | H11: 1.00 | N11: 9 | AE11: から コピー と コピーしたセルの挿入 | AL11: 9 | BC11: から コピー と コピーしたセルの挿入 | BJ11: 9 | CA11: から コピー と コピーしたセルの挿入 | CH11: 9
A12: =ROW() - 2 -> 10 | B12: を実行してください | C12: を実行してください | H12: 1.00 | N12: 10 | AE12: を実行してください | AL12: 10 | BC12: を実行してください | BJ12: 10 | CA12: を実行してください | CH12: 10
A13: =ROW() - 2 -> 11 | B13: settingscheck1check1 3. check1 に入れる文字列を記載する | C13: settingscheck1check1 3. check1 に入れる文字列を記載する | H13: 1.00 | N13: 11 | P13: settings | Q13: check1 | R13: check1 | AE13: 3. check1 に入れる文字列を記載する | AL13: 11 | AN13: settings | AO13: check1 | AP13: check1 | BC13: 3. check1 に入れる文字列を記載する | BJ13: 11 | BL13: settings | BM13: check1 | BN13: check1 | CA13: 3. check1 に入れる文字列を記載する | CH13: 11
A14: =ROW() - 2 -> 12 | B14: check2check2 4. check2 に入れる文字列を記載する | C14: check2check2 4. check2 に入れる文字列を記載する | H14: 1.00 | N14: 12 | Q14: check2 | R14: check2 | AE14: 4. check2 に入れる文字列を記載する | AL14: 12 | AO14: check2 | AP14: check2 | BC14: 4. check2 に入れる文字列を記載する | BJ14: 12 | BM14: check2 | BN14: check2 | CA14: 4. check2 に入れる文字列を記載する | CH14: 12
A15: =ROW() - 2 -> 13 | B15: reviewreview 5. review に入れる文字列を記載する | C15: reviewreview 5. review に入れる文字列を記載する | H15: 1.00 | N15: 13 | Q15: review | R15: review | AE15: 5. review に入れる文字列を記載する | AL15: 13 | AO15: review | AP15: review | BC15: 5. review に入れる文字列を記載する | BJ15: 13 | BM15: review | BN15: review | CA15: 5. review に入れる文字列を記載する | CH15: 13
A16: =ROW() - 2 -> 14 | B16: check✓ 6. リンクに使う文字列を記載する | C16: check✓ 6. リンクに使う文字列を記載する | H16: 1.00 | N16: 14 | Q16: check | R16: ✓ | AE16: 6. リンクに使う文字列を記載する | AL16: 14 | AO16: check | AP16: ✓ | BC16: 6. リンクに使う文字列を記載する | BJ16: 14 | BM16: check | BN16: ✓ | CA16: 6. リンクに使う文字列を記載する | CH16: 14
A17: =ROW() - 2 -> 15 | B17: is_exportFalse 7. 対象のデータをコピーしてローカルに | C17: is_exportFalse 7. 対象のデータをコピーしてローカルに | H17: 1.00 | N17: 15 | Q17: is_export | R17: FALSE | AE17: 7. 対象のデータをコピーしてローカルに | AL17: 15 | AO17: is_export | AP17: FALSE | BC17: 7. 対象のデータをコピーしてローカルに | BJ17: 15 | BM17: is_export | BN17: FALSE | CA17: 7. 対象のデータをコピーしてローカルに | CH17: 15
A18: =ROW() - 2 -> 16 | B18: listtitleflagkeywordpath 保存する場合に true を指定する | C18: listtitleflagkeywordpath 保存する場合に true を指定する | H18: 1.00 | N18: 16 | P18: list | Q18: title | R18: flag | S18: keyword | T18: path | AE18: 保存する場合に true を指定する | AL18: 16 | AN18: list | AO18: title | AP18: flag | AQ18: keyword | AR18: path | BC18: 保存する場合に true を指定する | BJ18: 16 | BL18: list | BM18: title | BN18: flag | BO18: keyword | BP18: path | CA18: 保存する場合に true を指定する | CH18: 16
A19: =ROW() - 2 -> 17 | B19: プロジェクト計画書fileplanc:\svn\trunk\prj\A/mng/ 8. 必要数、以下を繰り返す | C19: プロジェクト計画書fileplanc:\svn\trunk\prj\A/mng/ 8. 必要数、以下を繰り返す | H19: 1.00 | N19: 17 | Q19: プロジェクト計画書 | R19: file | S19: plan | T19: c:\svn\trunk\prj\A/mng/ | AE19: 8. 必要数、以下を繰り返す | AL19: 17 | AO19: プロジェクト計画書 | AP19: file | AQ19: plan | AR19: c:\svn\trunk\prj\A/mng/ | BC19: 8. 必要数、以下を繰り返す | BJ19: 17 | BM19: プロジェクト計画書 | BN19: file | BO19: plan | BP19: c:\svn\trunk\prj\A/mng/ | CA19: 8. 必要数、以下を繰り返す | CH19: 17
A20: =ROW() - 2 -> 18 | B20: リスク管理表fileriskc:\svn\trunk\prj\A/mng/ 1. title で 書類の名称として記載する文字列を指定する | C20: リスク管理表fileriskc:\svn\trunk\prj\A/mng/ 1. title で 書類の名称として記載する文字列を指定する | H20: 1.00 | N20: 18 | Q20: リスク管理表 | R20: file | S20: risk | T20: c:\svn\trunk\prj\A/mng/ | AE20: 1. title で 書類の名称として記載する文字列を指定する | AL20: 18 | AO20: リスク管理表 | AP20: file | AQ20: risk | AR20: c:\svn\trunk\prj\A/mng/ | BC20: 1. title で 書類の名称として記載する文字列を指定する | BJ20: 18 | BM20: リスク管理表 | BN20: file | BO20: risk | BP20: c:\svn\trunk\prj\A/mng/ | CA20: 1. title で 書類の名称として記載する文字列を指定する | CH20: 18
A21: =ROW() - 2 -> 19 | B21: 課題管理表fileissuec:\svn\trunk\prj\A/mng/ 2. flag で 検索対象を ファイル か ディレクトリ か選択する | C21: 課題管理表fileissuec:\svn\trunk\prj\A/mng/ 2. flag で 検索対象を ファイル か ディレクトリ か選択する | H21: 1.00 | N21: 19 | Q21: 課題管理表 | R21: file | S21: issue | T21: c:\svn\trunk\prj\A/mng/ | AE21: 2. flag で 検索対象を ファイル か ディレクトリ か選択する | AL21: 19 | AO21: 課題管理表 | AP21: file | AQ21: issue | AR21: c:\svn\trunk\prj\A/mng/ | BC21: 2. flag で 検索対象を ファイル か ディレクトリ か選択する | BJ21: 19 | BM21: 課題管理表 | BN21: file | BO21: issue | BP21: c:\svn\trunk\prj\A/mng/ | CA21: 2. flag で 検索対象を ファイル か ディレクトリ か選択する | CH21: 19
A22: =ROW() - 2 -> 20 | B22: システム仕様書filesystem_designc:\svn\trunk\prj\spec/ 3. keyword で 検索キーワードを指定する | C22: システム仕様書filesystem_designc:\svn\trunk\prj\spec/ 3. keyword で 検索キーワードを指定する | H22: 1.00 | N22: 20 | Q22: システム仕様書 | R22: file | S22: system_design | T22: c:\svn\trunk\prj\spec/ | AE22: 3. keyword で 検索キーワードを指定する | AL22: 20 | AO22: システム仕様書 | AP22: file | AQ22: system_design | AR22: c:\svn\trunk\prj\spec/ | BC22: 3. keyword で 検索キーワードを指定する | BJ22: 20 | BM22: システム仕様書 | BN22: file | BO22: system_design | BP22: c:\svn\trunk\prj\spec/ | CA22: 3. keyword で 検索キーワードを指定する | CH22: 20
A23: =ROW() - 2 -> 21 | B23: 4. path で 検索するパスの先頭パスを指定する | C23: 4. path で 検索するパスの先頭パスを指定する | H23: 1.00 | N23: 21 | AE23: 4. path で 検索するパスの先頭パスを指定する | AL23: 21 | BC23: 4. path で 検索するパスの先頭パスを指定する | BJ23: 21 | CA23: 4. path で 検索するパスの先頭パスを指定する | CH23: 21
A24: =ROW() - 2 -> 22 | B24: ※足りない場合は行を増やして下さい | C24: ※足りない場合は行を増やして下さい | H24: 1.00 | N24: 22 | AE24: ※足りない場合は行を増やして下さい | AL24: 22 | BC24: ※足りない場合は行を増やして下さい | BJ24: 22 | CA24: ※足りない場合は行を増やして下さい | CH24: 22
A25: =ROW() - 2 -> 23 | B25: 既存の行を選択、右クリックから コピー と コピーしたセルの挿入 を実行してください | C25: 既存の行を選択、右クリックから コピー と コピーしたセルの挿入 を実行してください | H25: 1.00 | N25: 23 | AE25: 既存の行を選択、右クリックから コピー と コピーしたセルの挿入 を実行してください | AL25: 23 | BC25: 既存の行を選択、右クリックから コピー と コピーしたセルの挿入 を実行してください | BJ25: 23 | CA25: 既存の行を選択、右クリックから コピー と コピーしたセルの挿入 を実行してください | CH25: 23
A26: =ROW() - 2 -> 24 | H26: 1.00 | N26: 24 | AL26: 24 | BJ26: 24 | CH26: 24
A27: =ROW() - 2 -> 25 | B27: ※参照パスリストをご活用いただいて、path の入力を計算式にすると他プロジェクトへの展開が容易になろうかと思います | C27: ※参照パスリストをご活用いただいて、path の入力を計算式にすると他プロジェクトへの展開が容易になろうかと思います | H27: 1.00 | N27: 25 | AE27: ※参照パスリストをご活用いただいて、path の入力を計算式にすると他プロジェクトへの展開が容易になろうかと思います | AL27: 25 | BC27: ※参照パスリストをご活用いただいて、path の入力を計算式にすると他プロジェクトへの展開が容易になろうかと思います | BJ27: 25 | CA27: ※参照パスリストをご活用いただいて、path の入力を計算式にすると他プロジェクトへの展開が容易になろうかと思います | CH27: 25
A28: =ROW() - 2 -> 26 | H28: 1.00 | N28: 26 | AL28: 26 | BJ28: 26 | CH28: 26
A29: =ROW() - 2 -> 27 | H29: 1.00 | N29: 27 | AL29: 27 | BJ29: 27 | CH29: 27
A30: =ROW() - 2 -> 28 | B30: <注意事項> | C30: <注意事項> | H30: 1.00 | N30: 28 | AE30: <注意事項> | AL30: 28 | BC30: <注意事項> | BJ30: 28 | CA30: <注意事項> | CH30: 28
A31: =ROW() - 2 -> 29 | B31: ツールが動作しなくなる可能性があるため、以下のことに注意いただきますようにお願い致します | C31: ツールが動作しなくなる可能性があるため、以下のことに注意いただきますようにお願い致します | H31: 1.00 | N31: 29 | AE31: ツールが動作しなくなる可能性があるため、以下のことに注意いただきますようにお願い致します | AL31: 29 | BC31: ツールが動作しなくなる可能性があるため、以下のことに注意いただきますようにお願い致します | BJ31: 29 | CA31: ツールが動作しなくなる可能性があるため、以下のことに注意いただきますようにお願い致します | CH31: 29
A32: =ROW() - 2 -> 30 | B32: ・入力欄以外の入力はしないようにお願い致します | C32: ・入力欄以外の入力はしないようにお願い致します | H32: 1.00 | N32: 30 | AE32: ・入力欄以外の入力はしないようにお願い致します | AL32: 30 | BC32: ・入力欄以外の入力はしないようにお願い致します | BJ32: 30 | CA32: ・入力欄以外の入力はしないようにお願い致します | CH32: 30
A33: =ROW() - 2 -> 31 | B33: ・シート名を変えないでください | C33: ・シート名を変えないでください | H33: 1.00 | N33: 31 | AE33: ・シート名を変えないでください | AL33: 31 | BC33: ・シート名を変えないでください | BJ33: 31 | CA33: ・シート名を変えないでください | CH33: 31
A34: =ROW() - 2 -> 32 | H34: 1.00 | N34: 32 | AL34: 32 | BJ34: 32 | CH34: 32
A35: =ROW() - 2 -> 33 | H35: 1.00 | N35: 33 | AL35: 33 | BJ35: 33 | CH35: 33
A36: =ROW() - 2 -> 34 | H36: 1.00 | N36: 34 | AL36: 34 | BJ36: 34 | CH36: 34
A37: =ROW() - 2 -> 35 | H37: 1.00 | N37: 35 | AL37: 35 | BJ37: 35 | CH37: 35
A38: =ROW() - 2 -> 36 | H38: 1.00 | N38: 36 | AL38: 36 | BJ38: 36 | CH38: 36
A39: =ROW() - 2 -> 37 | H39: 1.00 | N39: 37 | AL39: 37 | BJ39: 37 | CH39: 37
A40: =ROW() - 2 -> 38 | H40: 1.00 | N40: 38 | AL40: 38 | BJ40: 38 | CH40: 38
...

Sheet >>> ORG SHEET >>>

Sheet L_ii-path-maker
A1: ii-path-maker 操作説明書
B3: ■ 使い方 | BA3: ■ どういう使い方を想定しているか
C4: 設定ファイルを作成して、以下のいずれかのパターンで ii-path-maker に食わせます | AJ4: 例： とある svn のファイル構成 | BB4: 左記のような ファイル構成のとき、
AK5: c:\svn | BB5: 具体的には
C6: <パターン Drag&Drop> | R6: <パターン 送る> | AK6: +- repos | BC6: ・Aプロジェクトには派生プロジェクト(40)がある
AK7: | +- branches | BC7: ・派生プロジェクトにはスナップショットが存在する
AK8: | | +- A_404 | BC8: ・最新は trunk 以下に管理されている
AK9: | | | +- design | BC9: ・プロジェクトをまたいだ標準となる書類がある
AK10: | | | +- mng | BC10: ※trunk/prj/A 以外にも A で参照する資料がある
AK11: | | | | +- issue.xlsx
C12: <パターン ダブルクリック> | AK12: | | | | +- plan.xlsx
AK13: | | | | +- risk.xlsx | BB13: という状態で、
AK14: | | | +- spec | BB14: Aプロジェクトの情報を参照するにしても、
AK15: | | | | +- spec_system_design.xlsx | BB15: 経験をもとにどこに何があるか探しに行く
AK16: | +- tags | BB16: 必要がある
AK17: | | +- A_404_250122_DR
AK18: | | | +- design | BB18: そんなお困りごとを解決するために
AK19: | | | +- mng | BB19: ある程度ルールのある置き方がされている資料の
AK20: | | | | +- issue.xlsx | BB20: 一覧を作成するツールを用意しました
B21: ■ 結果の確認 | AK21: | | | | +- plan.xlsx
C22: 実行いただきますと、設定ファイルのあるディレクトリに以下のファイルが作成されます | AK22: | | | | +- risk.xlsx | BB22: 本ツールを使って、以下を指定することで
D23: ・結果帳票（設定ファイルの拡張子が xlsx に変わっているファイル） | AK23: | | | +- spec | BB23: ・資料の名称
D24: ※同名ファイルがあった場合、ii-path-maker_<ファイル名>_<数値>.xlsx を作成します | AK24: | | | | +- spec_system_design.xlsx | BB24: ・ファイル名・フォルダ名の検索キーワード
D25: ・実行前の設定ファイル（設定ファイル名と拡張子の間に _bk が入っているファイル） | AK25: | | +- A_404_250222_FIX | BB25: ・だいたいここらへんにあるはず！の所在
D26: ※同名ファイルがあった場合、上書きします | AK26: | | | +- design
D27: ・結果帳票にパスを記したファイルの現物 | AK27: | | | +- mng | BB27: プロジェクトの資料一覧を作成します
D28: ※設定ファイルの settings で is_export に true を指定した場合のみ作成されます | AK28: | | | | +- issue.xlsx
D29: ※同名ファイルがあった場合、ii-path-maker_<ファイル名>_<数値>.<拡張子> を作成します | AK29: | | | | +- plan.xlsx | BB29: オプション指定をすると
AK30: | | | | +- risk.xlsx | BB30: 資料を全て コピーして持ってきます
C31: 結果帳票は以下のようなものが出力されますので、出力後は自由にご活用くださいませ | AK31: | | | +- spec
AK32: | | | | +- spec_system_design.xlsx | BB32: ぜひ、ご活用くださいませ
AK33: | +- trunk
AK34: | | +- prj
AK35: | | | +- A
AK36: | | | | +- design
AK37: | | | | +- mng
AK38: | | | | | +- issue.xlsx
AK39: | | | | | +- plan.xlsx
AK40: | | | | | +- risk.xlsx
AK41: | | | +- B
...

Sheet R_ii-path-maker
A1: ii-path-maker 操作説明書
B3: ■ 使い方 | BA3: ■ どういう使い方を想定しているか
C4: 設定ファイルを作成して、以下のいずれかのパターンで ii-path-maker に食わせます | AJ4: 例： とある svn のファイル構成 | BB4: 左記のような ファイル構成のとき、
AK5: c:\svn | BB5: 具体的には
C6: <パターン Drag&Drop> | R6: <パターン 送る> | AK6: +- repos | BC6: ・Aプロジェクトには派生プロジェクト(404)がある
AK7: | +- branches | BC7: ・派生プロジェクトにはスナップショットが存在する
AK8: | | +- A_404 | BC8: ※マイルストーン毎に構成管理されており、
AK9: | | | +- design | BC9: 同じファイル名のファイルが複数存在する
AK10: | | | +- mng | BC10: ・最新は trunk 以下に管理されている
AK11: | | | | +- issue.xlsx | BC11: ・プロジェクトをまたいだ標準となる書類がある
C12: <パターン ダブルクリック> | AK12: | | | | +- plan.xlsx | BC12: ※trunk/prj/A 以外にも A で参照する資料がある
AK13: | | | | +- risk.xlsx | BB13: という状態で、
AK14: | | | +- spec | BB14: Aプロジェクトの情報を参照するにしても、
AK15: | | | | +- spec_system_design.xlsx | BB15: 経験をもとにどこに何があるか探しに行く
AK16: | +- tags | BB16: 必要がある
AK17: | | +- A_404_250122_DR
AK18: | | | +- design | BB18: そんなお困りごとを解決するために
AK19: | | | +- mng | BB19: ある程度ルールのある置き方がされている資料の
AK20: | | | | +- issue.xlsx | BB20: 一覧を作成するツールを用意しました
B21: ■ 結果の確認 | AK21: | | | | +- plan.xlsx
C22: 実行いただきますと、設定ファイルのあるディレクトリに以下のファイルが作成されます | AK22: | | | | +- risk.xlsx | BB22: 本ツールを使って、以下を指定することで
D23: ・結果帳票（設定ファイルの拡張子が xlsx に変わっているファイル） | AK23: | | | +- spec | BB23: ・資料の名称
D24: ※同名ファイルがあった場合、ii-path-maker_<ファイル名>_<数値>.xlsx を作成します | AK24: | | | | +- spec_system_design.xlsx | BB24: ・ファイル名・フォルダ名の検索キーワード
D25: ・実行前の設定ファイル（設定ファイル名と拡張子の間に _bk が入っているファイル） | AK25: | | +- A_404_250222_FIX | BB25: ・だいたいここらへんにあるはず！の所在
D26: ※同名ファイルがあった場合、上書きします | AK26: | | | +- design
D27: ・結果帳票にパスを記したファイルの現物 | AK27: | | | +- mng | BB27: プロジェクトの資料一覧を作成します
D28: ※設定ファイルの settings で is_export に true を指定した場合のみ作成されます | AK28: | | | | +- issue.xlsx
D29: ※同名ファイルがあった場合、ii-path-maker_<ファイル名>_<数値>.<拡張子> を作成します | AK29: | | | | +- plan.xlsx | BB29: オプション指定をすると
AK30: | | | | +- risk.xlsx | BB30: 資料を全て コピーして持ってきます
C31: 結果帳票は以下のようなものが出力されますので、出力後は自由にご活用くださいませ | AK31: | | | +- spec
AK32: | | | | +- spec_system_design.xlsx | BB32: ぜひ、ご活用くださいませ
AK33: | +- trunk
AK34: | | +- prj
AK35: | | | +- A
AK36: | | | | +- design
AK37: | | | | +- mng
AK38: | | | | | +- issue.xlsx
AK39: | | | | | +- plan.xlsx
AK40: | | | | | +- risk.xlsx
AK41: | | | +- B
...

Sheet L_ごみ settings
A1: プロジェクトＡ（ベース：Ｘ、派生：α）の開発資料リスト | Q1: ＜本シートの使い方> 1. タイトルを記載する
A3: 参照パスリスト | B3: name | C3: ドライブ | D3: svn | E3: プロジェクト | F3: 管理 | G3: 設計 | H3: 仕様 | U3: 入力欄
B4: path | C4: c:\svn\trunk\prj\ | D4: file:///c:/svn/repos/trunk/prj/ | E4: A/ | F4: mng/ | G4: design/ | H4: spec/
A6: 設定情報 | B6: description | C6: 派生αはベースＸから流用開発する | Q6: 2. description を記載する
C7: 仕様書を以下に列挙する | Q7: ※複数行可、１セル１行、行が不足した場合、
Q8: 7-9行目のいずれかを選択、右クリック
Q9: から コピー と コピーしたセルの挿入
Q10: を実行してください
B11: settings | C11: check1 | D11: check1 | Q11: 3. check1 に入れる文字列を記載する
C12: check2 | D12: check2 | Q12: 4. check2 に入れる文字列を記載する
C13: review | D13: review | Q13: 5. review に入れる文字列を記載する
C14: check | D14: ✓ | Q14: 6. リンクに使う文字列を記載する
C15: is_export | D15: FALSE | Q15: 7. 対象のデータをコピーしてローカルに
B16: list | C16: title | D16: flag | E16: keyword | F16: path | Q16: 保存する場合に true を指定する
C17: プロジェクト計画書 | D17: file | E17: plan | F17: c:\svn\trunk\prj\A/mng/ | Q17: 8. 必要数、以下を繰り返す
C18: リスク管理表 | D18: file | E18: risk | F18: c:\svn\trunk\prj\A/mng/ | Q18: 1. title で 書類の名称として記載する文字列を指定する
C19: 課題管理表 | D19: file | E19: issue | F19: c:\svn\trunk\prj\A/mng/ | Q19: 2. flag で 検索対象を ファイル か ディレクトリ か選択する
C20: システム仕様書 | D20: file | E20: system_design | F20: c:\svn\trunk\prj\spec/ | Q20: 3. keyword で 検索キーワードを指定する
Q21: 4. path で 検索するパスの先頭パスを指定する
Q22: ※足りない場合は行を増やして下さい
Q23: 既存の行を選択、右クリックから コピー と コピーしたセルの挿入 を実行してください
Q25: ※参照パスリストをご活用いただいて、path の入力を計算式にすると他プロジェクトへの展開が容易になろうかと思います
Q28: <注意事項>
Q29: ツールが動作しなくなる可能性があるため、以下のことに注意いただきますようにお願い致します
Q30: ・入力欄以外の入力はしないようにお願い致します
Q31: ・シート名を変えないでください

Sheet R_ごみ settings
A1: プロジェクトＡ（ベース：Ｘ、派生：α）の開発資料リスト | Q1: ＜本シートの使い方> 1. タイトルを記載する
A3: 参照パスリスト | B3: name | C3: ドライブ | D3: svn | E3: プロジェクト | F3: 管理 | G3: 設計 | H3: 仕様 | U3: 入力欄
B4: path | C4: c:\svn\trunk\prj\ | D4: file:///c:/svn/repos/trunk/prj/ | E4: A/ | F4: mng/ | G4: design/ | H4: spec/
A6: 設定情報 | B6: description | C6: 派生αはベースＸから流用開発する | Q6: 2. description を記載する
C7: 仕様書を以下に列挙する | Q7: ※複数行可、１セル１行、行が不足した場合、
Q8: 7-9行目のいずれかを選択、右クリック
Q9: から コピー と コピーしたセルの挿入
Q10: を実行してください
B11: settings | C11: check1 | D11: check1 | Q11: 3. check1 に入れる文字列を記載する
C12: check2 | D12: check2 | Q12: 4. check2 に入れる文字列を記載する
C13: review | D13: review | Q13: 5. review に入れる文字列を記載する
C14: check | D14: ✓ | Q14: 6. リンクに使う文字列を記載する
C15: is_export | D15: FALSE | Q15: 7. 対象のデータをコピーしてローカルに
B16: list | C16: title | D16: flag | E16: keyword | F16: path | Q16: 保存する場合に true を指定する
C17: プロジェクト計画書 | D17: file | E17: plan | F17: c:\svn\trunk\prj\A/mng/ | Q17: 8. 必要数、以下を繰り返す
C18: リスク管理表 | D18: file | E18: risk | F18: c:\svn\trunk\prj\A/mng/ | Q18: 1. title で 書類の名称として記載する文字列を指定する
C19: 課題管理表 | D19: file | E19: issue | F19: c:\svn\trunk\prj\A/mng/ | Q19: 2. flag で 検索対象を ファイル か ディレクトリ か選択する
C20: システム仕様書 | D20: file | E20: system_design | F20: c:\svn\trunk\prj\spec/ | Q20: 3. keyword で 検索キーワードを指定する
Q21: 4. path で 検索するパスの先頭パスを指定する
Q22: ※足りない場合は行を増やして下さい
Q23: 既存の行を選択、右クリックから コピー と コピーしたセルの挿入 を実行してください
Q25: ※参照パスリストをご活用いただいて、path の入力を計算式にすると他プロジェクトへの展開が容易になろうかと思います
Q28: <注意事項>
Q29: ツールが動作しなくなる可能性があるため、以下のことに注意いただきますようにお願い致します
Q30: ・入力欄以外の入力はしないようにお願い致します
Q31: ・シート名を変えないでください
